<?xml version="1.0"?>
<robot xmlns:xacro="https://www.ros.org/wiki/xacro" name="protobot">
	

<link name="base_link">
    <inertial>
         <mass value="3"/>
         <inertia ixx="1"  ixy="0"  ixz="0" iyy="1" iyz="0" izz="1" />
    </inertial>
    <visual>
        <origin xyz="0 0 0"/>
	<geometry>
	    <box size="1.0 1.2 0.5"/>
	</geometry>
	<material name="white"/>
    </visual>
    <collision>
	<geometry>
	    <box size="1 1.2 0.5"/>
	</geometry>
    </collision>
</link>

<link name="caster_link">
	<visual>
		<geometry>
			<cylinder length="0.15" radius="0.15"/>
		</geometry>
	</visual>
	<inertial>
           <origin xyz="0 0 0" rpy="0 0 0"/>
           <mass value="1"/>
           <inertia ixx="0.1"  ixy="0"  ixz="0" iyy="0.1" iyz="0" izz="0.1" />
    	</inertial>

</link>
<link name="left_wheel_link">
    <inertial>
         <origin xyz="0 0 0" rpy="0 0 0"/>
         <mass value="1"/>
         <inertia ixx="0.1"  ixy="0"  ixz="0" iyy="0.1" iyz="0" izz="0.1" />
    </inertial>
    <visual>
	    <geometry>
		    <cylinder length="0.15" radius="0.3"/>
	    </geometry>
    </visual>
    <collision>
	<geometry>
		    <cylinder length="0.15" radius="0.3"/>
	    </geometry>
    </collision>

</link>

<link name="right_wheel_link">
    <inertial>
         <origin xyz="0 0 0" rpy="0 0 0"/>
         <mass value="1"/>
         <inertia ixx="0.1"  ixy="0"  ixz="0" iyy="0.1" iyz="0" izz="0.1" />
    </inertial>
    <visual>
	    <geometry>
		    <cylinder length="0.15" radius="0.3"/>
	    </geometry>
    </visual>
    <collision>
	<geometry>
		    <cylinder length="0.15" radius="0.3"/>
	    </geometry>
    </collision>
</link>

<link name="gps_imu_link">
</link>

<link name="camera_link">
</link>

<link name="camera_link_optical">
</link>

<link name="ir_link">
</link>

<joint name="caster_joint" type="continuous">
	<parent link="base_link"/>
	<child link="caster_link"/>
	<axis xyz="0 0 1"/>
	<origin xyz="0 0.2 -0.1" rpy="0 1.57 0" />
</joint>

<joint name="camera_joint" type="fixed">
	<parent link="base_link"/>
	<child link="camera_link"/>
	<origin xyz="0 -0.5 0.5" rpy="3.1415 3.1415 1.571"/>
	<!--<origin xyz="0 0.5 0.5" rpy="0 0 1.57"/>-->
</joint>

<joint name="camera_optical_joint" type="fixed">
	<parent link="camera_link"/>
	<child link="camera_link_optical"/>
	<origin xyz="0 0 0" rpy="1.571 3.14 1.571"/>
</joint>


<joint name="ir_joint" type="fixed">
	<parent link="base_link"/>
	<child link="ir_link"/>
	<origin xyz="0 0 -0.25"/>
</joint>


<joint name="right_wheel_joint" type="continuous">
	<parent link="base_link"/>
	<child link="right_wheel_link"/>
	<origin xyz="-0.6 0.0 0" rpy="0 1.57 0"/>
	<axis xyz="0 0 1"/>
</joint>


<joint name="left_wheel_joint" type="continuous">
	<parent link = "base_link"/>
	<child link = "left_wheel_link"/>
	<origin xyz="0.6 0 0" rpy="0 1.57 0"/>
	<axis xyz="0 0 1"/>
</joint>

<joint name="gps_imu_joint" type="fixed">
	<parent link="base_link"/>
	<child link="gps_imu_link"/>
	<origin xyz="0 0 0.5"/>
</joint>

<material name="white">
	<color rgba="1 1 1 1"/>
</material>
<gazebo>    
     <plugin name="imu_plugin" filename="libgazebo_ros_imu.so">
      <alwaysOn>true</alwaysOn>
      <bodyName>gps_imu_link</bodyName>
      <topicName>imu/data</topicName>
      <serviceName>imu_service</serviceName>
      <gaussianNoise>0</gaussianNoise>
      <updateRate>20.0</updateRate>
    </plugin>
</gazebo>

<gazebo>
	<plugin name="gps_controller" filename="libhector_gazebo_ros_gps.so">
		<updateRate>30.0</updateRate>
		<bodyName>gps_imu_link</bodyName>
		<topicName>gps/fix</topicName>
		<frameId>gps_imu_link</frameId>
		<gaussianNoise>0</gaussianNoise>
	</plugin>
</gazebo>

<gazebo reference="camera_link">
     <sensor type="depth" name="depth_camera">
      <plugin name="camera_link_controller" filename="libgazebo_ros_openni_kinect.so">
          <baseline>0.2</baseline>
          <alwaysOn>true</alwaysOn>
          <updateRate>1.0</updateRate>
          <cameraName>camera</cameraName>
          <imageTopicName>color/image_raw</imageTopicName>
	  <cameraInfoTopicName>color/camera_info</cameraInfoTopicName>
	  <depthImageTopicName>depth/image_raw</depthImageTopicName>
	  <depthImageInfoTopicName>depth/camera_info</depthImageInfoTopicName>
	  <pointCloudTopicName>depth/pointcloud</pointCloudTopicName>
          <frameName>camera_link_optical</frameName>
          <pointCloudCutoff>0.1</pointCloudCutoff>
	  <pointCloudCutoffMax>5</pointCloudCutoffMax>
          <distortionK1>0.00000001</distortionK1>
          <distortionK2>0.00000001</distortionK2>
          <distortionK3>0.00000001</distortionK3>
          <distortionT1>0.00000001</distortionT1>
          <distortionT2>0.00000001</distortionT2>
          <CxPrime>0</CxPrime>
          <Cx>0</Cx>
          <Cy>0</Cy>
          <focalLength>0</focalLength>
          <hackBaseline>0</hackBaseline>	
      </plugin>
     </sensor>
  </gazebo>
</robot>
