<?xml version="1.0"?>
<robot xmlns:xacro="https://www.ros.org/wiki/xacro" name="protobot">
	
<xacro:include filename="$(find protobot_description)/urdf/protobot.gazebo.xacro"/>

<link name="base_link">
    <inertial>
         <mass value="3"/>
         <inertia ixx="1"  ixy="0"  ixz="0" iyy="1" iyz="0" izz="1" />
    </inertial>
    <visual>
        <origin xyz="0 0 0"/>
	<geometry>
	    <box size="1.0 1.2 0.5"/>
	</geometry>
	<material name="white"/>
    </visual>
    <collision>
	<geometry>
	    <box size="1 1.2 0.5"/>
	</geometry>
    </collision>
</link>

<link name="caster_link">
	<visual>
		<geometry>
			<cylinder length="0.15" radius="0.15"/>
		</geometry>
	</visual>
	<inertial>
           <origin xyz="0 0 0" rpy="0 0 0"/>
           <mass value="1"/>
           <inertia ixx="0.1"  ixy="0"  ixz="0" iyy="0.1" iyz="0" izz="0.1" />
    	</inertial>

</link>
<link name="left_wheel_link">
    <inertial>
         <origin xyz="0 0 0" rpy="0 0 0"/>
         <mass value="1"/>
         <inertia ixx="0.1"  ixy="0"  ixz="0" iyy="0.1" iyz="0" izz="0.1" />
    </inertial>
    <visual>
	    <geometry>
		    <cylinder length="0.15" radius="0.3"/>
	    </geometry>
    </visual>
    <collision>
	<geometry>
		    <cylinder length="0.15" radius="0.3"/>
	    </geometry>
    </collision>

</link>

<link name="right_wheel_link">
    <inertial>
         <origin xyz="0 0 0" rpy="0 0 0"/>
         <mass value="1"/>
         <inertia ixx="0.1"  ixy="0"  ixz="0" iyy="0.1" iyz="0" izz="0.1" />
    </inertial>
    <visual>
	    <geometry>
		    <cylinder length="0.15" radius="0.3"/>
	    </geometry>
    </visual>
    <collision>
	<geometry>
		    <cylinder length="0.15" radius="0.3"/>
	    </geometry>
    </collision>
</link>

<link name="gps_imu_link">
</link>

<link name="camera_link">
</link>

<link name="camera_link_optical">
</link>

<link name="ir_link">
</link>

<joint name="caster_joint" type="continuous">
	<parent link="base_link"/>
	<child link="caster_link"/>
	<axis xyz="0 0 1"/>
	<origin xyz="0 0.2 -0.1" rpy="0 1.57 0" />
</joint>

<joint name="camera_joint" type="fixed">
	<parent link="base_link"/>
	<child link="camera_link"/>
	<origin xyz="0 -0.5 0.5" rpy="3.1415 3.1415 1.571"/>
	<!--<origin xyz="0 0.5 0.5" rpy="0 0 1.57"/>-->
</joint>

<joint name="camera_optical_joint" type="fixed">
	<parent link="camera_link"/>
	<child link="camera_link_optical"/>
	<origin xyz="0 0 0" rpy="1.571 3.14 1.571"/>
</joint>


<joint name="ir_joint" type="fixed">
	<parent link="base_link"/>
	<child link="ir_link"/>
	<origin xyz="0 0 -0.25"/>
</joint>


<joint name="right_wheel_joint" type="continuous">
	<parent link="base_link"/>
	<child link="right_wheel_link"/>
	<origin xyz="-0.6 0.0 0" rpy="0 1.57 0"/>
	<axis xyz="0 0 1"/>
</joint>


<joint name="left_wheel_joint" type="continuous">
	<parent link = "base_link"/>
	<child link = "left_wheel_link"/>
	<origin xyz="0.6 0 0" rpy="0 1.57 0"/>
	<axis xyz="0 0 1"/>
</joint>

<joint name="gps_imu_joint" type="fixed">
	<parent link="base_link"/>
	<child link="gps_imu_link"/>
	<origin xyz="0 0 0.5"/>
</joint>

<material name="white">
	<color rgba="1 1 1 1"/>
</material>
<gazebo>    
     <plugin name="imu_plugin" filename="libgazebo_ros_imu.so">
      <alwaysOn>true</alwaysOn>
      <bodyName>gps_imu_link</bodyName>
      <topicName>imu/data</topicName>
      <serviceName>imu_service</serviceName>
      <gaussianNoise>0</gaussianNoise>
      <updateRate>20.0</updateRate>
    </plugin>
</gazebo>

<gazebo>
	<plugin name="gps_controller" filename="libhector_gazebo_ros_gps.so">
		<updateRate>5.0</updateRate>
		<bodyName>gps_imu_link</bodyName>
		<topicName>gps/fix</topicName>
		<frameId>gps_imu_link</frameId>
		<gaussianNoise>0.2</gaussianNoise>
	</plugin>
</gazebo>
<gazebo>
  <plugin name="differential_drive_controller" filename="libgazebo_ros_diff_drive.so">

    <alwaysOn>true</alwaysOn>
    <!-- Plugin update rate in Hz -->
    <updateRate>20</updateRate>

    <!-- Name of left joint, defaults to `left_joint` -->
    <leftJoint>left_wheel_joint</leftJoint>

    <!-- Name of right joint, defaults to `right_joint` -->
    <rightJoint>right_wheel_joint</rightJoint>

    <!-- The distance from the center of one wheel to the other, in meters, defaults to 0.34 m -->
    <wheelSeparation>0.5380</wheelSeparation>

    <!-- Diameter of the wheels, in meters, defaults to 0.15 m -->
    <wheelDiameter>0.5</wheelDiameter>

    <!-- Wheel acceleration, in rad/s^2, defaults to 0.0 rad/s^2 -->
    <wheelAcceleration>1.0</wheelAcceleration>

    <!-- Maximum torque which the wheels can produce, in Nm, defaults to 5 Nm -->
    <wheelTorque>20</wheelTorque>

    <!-- Topic to receive geometry_msgs/Twist message commands, defaults to `cmd_vel` -->
    <commandTopic>cmd_vel</commandTopic>

    <!-- Topic to publish nav_msgs/Odometry messages, defaults to `odom` -->
    <odometryTopic>localization/unfiltered/wheel_odom</odometryTopic>

    <!-- Odometry frame, defaults to `odom` -->
    <odometryFrame>odom</odometryFrame>

    <!-- Robot frame to calculate odometry from, defaults to `base_footprint` -->
    <robotBaseFrame>base_link</robotBaseFrame>

    <!-- Odometry source, 0 for ENCODER, 1 for WORLD, defaults to WORLD -->
    <odometrySource>0</odometrySource>

    <!-- Set to true to publish transforms for the wheel links, defaults to false -->
    <publishWheelTF>false</publishWheelTF>

    <!-- Set to true to publish transforms for the odometry, defaults to true -->
    <publishOdom>true</publishOdom>

    <publishOdomTF>false</publishOdomTF>

    <!-- Set to true to publish sensor_msgs/JointState on /joint_states for the wheel joints, defaults to false -->
    <publishWheelJointState>false</publishWheelJointState>

    <!-- Set to true to swap right and left wheels, defaults to true -->
    <legacyMode>false</legacyMode>
  </plugin>
</gazebo>

<gazebo reference="camera_link">
    <sensor type="multicamera" name="stereo_camera">
      <update_rate>30.0</update_rate>
      <camera name="left">
        <horizontal_fov>1.6428</horizontal_fov>
        <image>
          <width>1920</width>
          <height>1080</height>
          <format>R8G8B8</format>
        </image>
        <clip>
          <near>0.02</near>
          <far>300</far>
        </clip>
        <noise>
          <type>gaussian</type>
          <mean>0.0</mean>
          <stddev>0.007</stddev>
        </noise>
      </camera>
      <camera name="right">
        <pose>0 -0.07 0 0 0 0</pose>
        <horizontal_fov>1.6248</horizontal_fov>
        <image>
          <width>1920</width>
          <height>1080</height>
          <format>R8G8B8</format>
        </image>
        <clip>
          <near>0.02</near>
          <far>300</far>
        </clip>
        <noise>
          <type>gaussian</type>
          <mean>0.0</mean>
          <stddev>0.007</stddev>
        </noise>
</camera>
      <plugin name="stereo_camera_controller" filename="libgazebo_ros_multicamera.so">
        <alwaysOn>true</alwaysOn>
        <updateRate>0.0</updateRate>
        <cameraName>camera</cameraName>
        <imageTopicName>image_color_rect</imageTopicName>
        <cameraInfoTopicName>camera_info</cameraInfoTopicName>
        <frameName>camera_link</frameName>
        <hackBaseline>0.07</hackBaseline>
        <distortionK1>0.0</distortionK1>
        <distortionK2>0.0</distortionK2>
        <distortionK3>0.0</distortionK3>
        <distortionT1>0.0</distortionT1>
        <distortionT2>0.0</distortionT2>
     </plugin> 
     </sensor>
     <sensor type="depth" name="depth_camera">
      <plugin name="camera_link_controller" filename="libgazebo_ros_openni_kinect.so">
          <baseline>0.2</baseline>
          <alwaysOn>true</alwaysOn>
          <updateRate>1.0</updateRate>
          <cameraName>camera</cameraName>
          <imageTopicName>camera_gazebo/color/image_raw</imageTopicName>
          <cameraInfoTopicName>camera_gazebo/color/camera_info</cameraInfoTopicName>
          <depthImageTopicName>camera_gazebo/depth/image_raw</depthImageTopicName>
          <depthImageInfoTopicName>camera_gazebo/depth/camera_info</depthImageInfoTopicName>
	  <pointCloudTopicName>depth_camera/pointcloud</pointCloudTopicName>
          <frameName>camera_link_optical</frameName>
          <pointCloudCutoff>0.1</pointCloudCutoff>
          <pointCloudCutoffMax>5</pointCloudCutoffMax>
          <distortionK1>0.00000001</distortionK1>
          <distortionK2>0.00000001</distortionK2>
          <distortionK3>0.00000001</distortionK3>
          <distortionT1>0.00000001</distortionT1>
          <distortionT2>0.00000001</distortionT2>
          <CxPrime>0</CxPrime>
          <Cx>0</Cx>
          <Cy>0</Cy>
          <focalLength>0</focalLength>
          <hackBaseline>0</hackBaseline>	
      </plugin>
 
     </sensor>
  </gazebo>
</robot>
